INFO  | 06/29/2022 06:04:24 AM | File run_exp.py           | Line 26    | Writing log file to /home/alex/Projects/GRAN_social/exp/GRAN/FACEBOOK_LARGE/log_exp_16889.txt
INFO  | 06/29/2022 06:04:24 AM | File run_exp.py           | Line 27    | Exp instance id = 16889
INFO  | 06/29/2022 06:04:24 AM | File run_exp.py           | Line 28    | Exp comment = None
INFO  | 06/29/2022 06:04:24 AM | File run_exp.py           | Line 29    | Config =
ERROR | 06/29/2022 06:04:24 AM | File run_exp.py           | Line 46    | Traceback (most recent call last):
  File "/home/alex/Projects/GRAN_social/run_exp.py", line 36, in main
    runner = eval(config.runner)(config)
  File "/home/alex/Projects/GRAN_social/runner/gran_runner.py", line 120, in __init__
    self.graphs = create_graphs(config.dataset.name, data_dir=config.dataset.data_path)
  File "/home/alex/Projects/GRAN_social/utils/data_helper.py", line 250, in create_graphs
    print('max # nodes = {} || mean # nodes = {}'.format(max(num_nodes), np.mean(num_nodes)))
ValueError: max() arg is an empty sequence

