INFO  | 06/23/2022 10:39:51 AM | File run_exp.py           | Line 26    | Writing log file to /home/alex/Documents/Project_CDT/GRAN_social/exp/GRAN/FACEBOOK_LARGE/log_exp_1797201.txt
INFO  | 06/23/2022 10:39:51 AM | File run_exp.py           | Line 27    | Exp instance id = 1797201
INFO  | 06/23/2022 10:39:51 AM | File run_exp.py           | Line 28    | Exp comment = None
INFO  | 06/23/2022 10:39:51 AM | File run_exp.py           | Line 29    | Config =
INFO  | 06/23/2022 10:40:05 AM | File gran_runner.py       | Line 135   | Train/val/test = 160/40/40
INFO  | 06/23/2022 10:40:07 AM | File gran_runner.py       | Line 148   | No Edges vs. Edges in training set = 89.22312601985614
ERROR | 06/23/2022 10:40:07 AM | File run_exp.py           | Line 46    | Traceback (most recent call last):
  File "run_exp.py", line 42, in main
    runner.generate()
  File "/home/alex/Documents/Project_CDT/GRAN_social/runner/gran_runner.py", line 455, in generate
    load_model(model, model_file, self.device)
  File "/home/alex/Documents/Project_CDT/GRAN_social/utils/train_helper.py", line 48, in load_model
    model_snapshot = torch.load(file_name, map_location=device)
  File "/home/alex/anaconda3/lib/python3.8/site-packages/torch/serialization.py", line 579, in load
    with _open_file_like(f, 'rb') as opened_file:
  File "/home/alex/anaconda3/lib/python3.8/site-packages/torch/serialization.py", line 230, in _open_file_like
    return _open_file(name_or_buffer, mode)
  File "/home/alex/anaconda3/lib/python3.8/site-packages/torch/serialization.py", line 211, in __init__
    super(_open_file, self).__init__(open(name, mode))
FileNotFoundError: [Errno 2] No such file or directory: '/home/alex/Documents/Project_CDT/GRAN_social/exp/GRAN/FACEBOOK_LARGE/model_snapshot_00001000.pth'

